Workbook

Sheet Readme
B2: INDIA CPI INFLATION ANALYSIS
B5: EXCEL DATA ANALYTICS CASE STUDY | CODING NINJAS
B7: 1. PROJECT OVERVIEW
B8: This workbook analyzes India's Consumer Price Index (CPI) data to identify category contribution, year-over-year inflation trends, food inflation dynamics, the impact of COVID-19, and the relationship between imported crude oil price movements and CPI category inflation. The workbook is structured as a case-study analysis with an executive Dashboard, five question-specific analysis sheets and supporting calculations.
B12: 2. DATA SOURCE & COVERAGE
B13: Data source | F13: Government Of India, Ministry of Statistics and Programme Implementation
B14: CPI data coverage | F14: January 2013 to May 2023
B15: Sectors | F15: Rural | Urban | Rural + Urban (Combined)
B17: 3. WORKBOOK STRUCTURE
B18: Dashboard | F18: Executive summary of the five case-study questions with navigation to detailed analysis.
B19: Q1 - CPI Contribution | F19: Latest-month broader-category contribution analysis for Rural, Urban and Rural + Urban.
B20: Q2 - YoY Inflation | F20: May-to-May YoY CPI inflation trend from 2017 to 2023 and peak-year research.
B21: Q3 - Food Inflation | F21: 12-month Food-bucket MoM trend, high/low months and food sub-category index changes.
B22: Q4 - COVID Impact | F22: March 2017–March 2023 comparison around the March 2020 COVID-19 onset.
B23: Q5 - Oil Impact | F23: Monthly imported crude oil changes vs CPI category inflation and Pearson correlation.
B24: Data_Dictionary | F24: Definitions, field descriptions, cleaning/validation notes and derived metrics.
B25: Cleaned_Data | F25: Analysis-ready CPI table after structural cleaning/standardization.
B26: Dashboard_Calculations | F26: Helper calculations used to populate dashboard cards, shapes and summary values.
B27: Raw_Data | F27: Original source dataset retained as the source/reference layer.
B29: 4. CORE ANALYTICAL METHODS
B30: Method | F30: Definition / Use
B31: MoM inflation | F31: [(Current CPI Index − Previous Month CPI Index) / Previous Month CPI Index] × 100
B32: YoY inflation | F32: [(Current CPI Index − Same Month Previous Year CPI Index) / Same Month Previous Year CPI Index] × 100
B33: CPI contribution | F33: Broader-category CPI index ÷ total analyzed broader-category index × 100; each sector totals 100%.
B34: Q3 Food bucket | F34: Simple average of the 12 specified Food sub-category CPI indices, consistent with the case-study equal-weight assumption.
B35: Q5 correlation | F35: Pearson correlation using Excel CORREL() between imported crude oil MoM changes and CPI category MoM changes.
B36: Correlation interpretation | F36: Correlation describes association; it does not by itself establish causation.
B38: 5. KEY ASSUMPTIONS & SCOPE
B39: • Equal weights across categories are used where specified by the case study. • Broader categories are created by grouping related CPI sub-categories for analytical purposes. • March 2020 is treated as the COVID-19 onset for Q4. • Dec-2020 is used as the base month for the Jan-2021 imported-oil MoM calculation in Q5. • Q2 uses a May-to-May YoY comparison, consistent with the instruction that any month may be used as the start of the year. • Q3 'absolute change' refers to the change in CPI index points between Jun-2022 and May-2023, not a percentage contribution to inflation.
B47: *Raw_Data is protected to prevent accidental modification of the original dataset. Password: SATYAM

Sheet Dashboard

Sheet Q1 - CPI Contribution
E19: e
B23: Categories | C23: Of May 2023 Rural | D23: of May 2023 Urban | E23: of May 2023 Rural+Urban
B24: Food | C24: 0.51169152 | D24: 0.50298002 | E24: 0.49609475
B25: Apparel | C25: 0.091765105 | D25: 0.081664135 | E25: 0.085565736
B26: Pan, tobacco and intoxicants | C26: 0.048387878 | D26: 0.047727007 | E26: 0.046862978
B27: Health | C27: 0.045458947 | D27: 0.042585018 | E27: 0.043295796
B28: Personal care and effects | C28: 0.044756971 | D28: 0.043379689 | E28: 0.043179222
B29: Fuel and light | C29: 0.044176026 | D29: 0.04286549 | E29: 0.042619664
B30: Education | C30: 0.043643493 | D30: 0.04085544 | E30: 0.041290714
B31: Household goods and services | C31: 0.043522463 | D31: 0.039756924 | E31: 0.04084773
B32: Miscellaneous | C32: 0.043449845 | D32: 0.040107514 | E32: 0.040964305
B33: Recreation and amusement | C33: 0.042070101 | D33: 0.03954657 | E33: 0.039915134
B34: Transport and communication | C34: 0.041077653 | D34: 0.037489774 | E34: 0.038422979
B35: Housing | C35: 0 | D35: 0.041042421 | E35: 0.04094099
B36: Grand Total | C36: 1 | D36: 1 | E36: 1
B47: Category | C47: Broader Category | D47: May 2023 Rural | E47: May 2023 Urban | F47: May 2023 Rural+Urban
B48: Cereals and products | C48: Food | D48: {=INDEX(CPI_Data[#All], MATCH("Rural"&"2023"&"May",CPI_Data[[#All],[Sector]]&CPI_Data[[#All],[Year]]&CPI_Data[[#All],[Month]],0), MATCH('Q1 - CPI Contribution'!B48,CPI_Data[#Headers],0))} -> 173.2 | E48: {=INDEX(CPI_Data[#All], MATCH("Urban"&"2023"&"May",CPI_Data[[#All],[Sector]]&CPI_Data[[#All],[Year]]&CPI_Data[[#All],[Month]],0), MATCH('Q1 - CPI Contribution'!B48,CPI_Data[#Headers],0))} -> 174.7 | F48: {=INDEX(CPI_Data[#All], MATCH("Rural+Urban"&"2023"&"May",CPI_Data[[#All],[Sector]]&CPI_Data[[#All],[Year]]&CPI_Data[[#All],[Month]],0), MATCH('Q1 - CPI Contribution'!B48,CPI_Data[#Headers],0))} -> 173.7
B49: Meat and fish | C49: Food | D49: {=INDEX(CPI_Data[#All], MATCH("Rural"&"2023"&"May",CPI_Data[[#All],[Sector]]&CPI_Data[[#All],[Year]]&CPI_Data[[#All],[Month]],0), MATCH('Q1 - CPI Contribution'!B49,CPI_Data[#Headers],0))} -> 211.5 | E49: {=INDEX(CPI_Data[#All], MATCH("Urban"&"2023"&"May",CPI_Data[[#All],[Sector]]&CPI_Data[[#All],[Year]]&CPI_Data[[#All],[Month]],0), MATCH('Q1 - CPI Contribution'!B49,CPI_Data[#Headers],0))} -> 219.4 | F49: {=INDEX(CPI_Data[#All], MATCH("Rural+Urban"&"2023"&"May",CPI_Data[[#All],[Sector]]&CPI_Data[[#All],[Year]]&CPI_Data[[#All],[Month]],0), MATCH('Q1 - CPI Contribution'!B49,CPI_Data[#Headers],0))} -> 214.3
B50: Egg | C50: Food | D50: {=INDEX(CPI_Data[#All], MATCH("Rural"&"2023"&"May",CPI_Data[[#All],[Sector]]&CPI_Data[[#All],[Year]]&CPI_Data[[#All],[Month]],0), MATCH('Q1 - CPI Contribution'!B50,CPI_Data[#Headers],0))} -> 171 | E50: {=INDEX(CPI_Data[#All], MATCH("Urban"&"2023"&"May",CPI_Data[[#All],[Sector]]&CPI_Data[[#All],[Year]]&CPI_Data[[#All],[Month]],0), MATCH('Q1 - CPI Contribution'!B50,CPI_Data[#Headers],0))} -> 176.7 | F50: {=INDEX(CPI_Data[#All], MATCH("Rural+Urban"&"2023"&"May",CPI_Data[[#All],[Sector]]&CPI_Data[[#All],[Year]]&CPI_Data[[#All],[Month]],0), MATCH('Q1 - CPI Contribution'!B50,CPI_Data[#Headers],0))} -> 173.2
B51: Milk and products | C51: Food | D51: {=INDEX(CPI_Data[#All], MATCH("Rural"&"2023"&"May",CPI_Data[[#All],[Sector]]&CPI_Data[[#All],[Year]]&CPI_Data[[#All],[Month]],0), MATCH('Q1 - CPI Contribution'!B51,CPI_Data[#Headers],0))} -> 179.6 | E51: {=INDEX(CPI_Data[#All], MATCH("Urban"&"2023"&"May",CPI_Data[[#All],[Sector]]&CPI_Data[[#All],[Year]]&CPI_Data[[#All],[Month]],0), MATCH('Q1 - CPI Contribution'!B51,CPI_Data[#Headers],0))} -> 179.4 | F51: {=INDEX(CPI_Data[#All], MATCH("Rural+Urban"&"2023"&"May",CPI_Data[[#All],[Sector]]&CPI_Data[[#All],[Year]]&CPI_Data[[#All],[Month]],0), MATCH('Q1 - CPI Contribution'!B51,CPI_Data[#Headers],0))} -> 179.5
B52: Oils and fats | C52: Food | D52: {=INDEX(CPI_Data[#All], MATCH("Rural"&"2023"&"May",CPI_Data[[#All],[Sector]]&CPI_Data[[#All],[Year]]&CPI_Data[[#All],[Month]],0), MATCH('Q1 - CPI Contribution'!B52,CPI_Data[#Headers],0))} -> 173.3 | E52: {=INDEX(CPI_Data[#All], MATCH("Urban"&"2023"&"May",CPI_Data[[#All],[Sector]]&CPI_Data[[#All],[Year]]&CPI_Data[[#All],[Month]],0), MATCH('Q1 - CPI Contribution'!B52,CPI_Data[#Headers],0))} -> 164.4 | F52: {=INDEX(CPI_Data[#All], MATCH("Rural+Urban"&"2023"&"May",CPI_Data[[#All],[Sector]]&CPI_Data[[#All],[Year]]&CPI_Data[[#All],[Month]],0), MATCH('Q1 - CPI Contribution'!B52,CPI_Data[#Headers],0))} -> 170
B53: Fruits | C53: Food | D53: {=INDEX(CPI_Data[#All], MATCH("Rural"&"2023"&"May",CPI_Data[[#All],[Sector]]&CPI_Data[[#All],[Year]]&CPI_Data[[#All],[Month]],0), MATCH('Q1 - CPI Contribution'!B53,CPI_Data[#Headers],0))} -> 169 | E53: {=INDEX(CPI_Data[#All], MATCH("Urban"&"2023"&"May",CPI_Data[[#All],[Sector]]&CPI_Data[[#All],[Year]]&CPI_Data[[#All],[Month]],0), MATCH('Q1 - CPI Contribution'!B53,CPI_Data[#Headers],0))} -> 175.8 | F53: {=INDEX(CPI_Data[#All], MATCH("Rural+Urban"&"2023"&"May",CPI_Data[[#All],[Sector]]&CPI_Data[[#All],[Year]]&CPI_Data[[#All],[Month]],0), MATCH('Q1 - CPI Contribution'!B53,CPI_Data[#Headers],0))} -> 172.2
B54: Vegetables | C54: Food | D54: {=INDEX(CPI_Data[#All], MATCH("Rural"&"2023"&"May",CPI_Data[[#All],[Sector]]&CPI_Data[[#All],[Year]]&CPI_Data[[#All],[Month]],0), MATCH('Q1 - CPI Contribution'!B54,CPI_Data[#Headers],0))} -> 148.7 | E54: {=INDEX(CPI_Data[#All], MATCH("Urban"&"2023"&"May",CPI_Data[[#All],[Sector]]&CPI_Data[[#All],[Year]]&CPI_Data[[#All],[Month]],0), MATCH('Q1 - CPI Contribution'!B54,CPI_Data[#Headers],0))} -> 185 | F54: {=INDEX(CPI_Data[#All], MATCH("Rural+Urban"&"2023"&"May",CPI_Data[[#All],[Sector]]&CPI_Data[[#All],[Year]]&CPI_Data[[#All],[Month]],0), MATCH('Q1 - CPI Contribution'!B54,CPI_Data[#Headers],0))} -> 161
B55: Pulses and products | C55: Food | D55: {=INDEX(CPI_Data[#All], MATCH("Rural"&"2023"&"May",CPI_Data[[#All],[Sector]]&CPI_Data[[#All],[Year]]&CPI_Data[[#All],[Month]],0), MATCH('Q1 - CPI Contribution'!B55,CPI_Data[#Headers],0))} -> 174.9 | E55: {=INDEX(CPI_Data[#All], MATCH("Urban"&"2023"&"May",CPI_Data[[#All],[Sector]]&CPI_Data[[#All],[Year]]&CPI_Data[[#All],[Month]],0), MATCH('Q1 - CPI Contribution'!B55,CPI_Data[#Headers],0))} -> 176.9 | F55: {=INDEX(CPI_Data[#All], MATCH("Rural+Urban"&"2023"&"May",CPI_Data[[#All],[Sector]]&CPI_Data[[#All],[Year]]&CPI_Data[[#All],[Month]],0), MATCH('Q1 - CPI Contribution'!B55,CPI_Data[#Headers],0))} -> 175.6
B56: Sugar and Confectionery | C56: Food | D56: {=INDEX(CPI_Data[#All], MATCH("Rural"&"2023"&"May",CPI_Data[[#All],[Sector]]&CPI_Data[[#All],[Year]]&CPI_Data[[#All],[Month]],0), MATCH('Q1 - CPI Contribution'!B56,CPI_Data[#Headers],0))} -> 121.9 | E56: {=INDEX(CPI_Data[#All], MATCH("Urban"&"2023"&"May",CPI_Data[[#All],[Sector]]&CPI_Data[[#All],[Year]]&CPI_Data[[#All],[Month]],0), MATCH('Q1 - CPI Contribution'!B56,CPI_Data[#Headers],0))} -> 124.2 | F56: {=INDEX(CPI_Data[#All], MATCH("Rural+Urban"&"2023"&"May",CPI_Data[[#All],[Sector]]&CPI_Data[[#All],[Year]]&CPI_Data[[#All],[Month]],0), MATCH('Q1 - CPI Contribution'!B56,CPI_Data[#Headers],0))} -> 122.7
B57: Spices | C57: Food | D57: {=INDEX(CPI_Data[#All], MATCH("Rural"&"2023"&"May",CPI_Data[[#All],[Sector]]&CPI_Data[[#All],[Year]]&CPI_Data[[#All],[Month]],0), MATCH('Q1 - CPI Contribution'!B57,CPI_Data[#Headers],0))} -> 221 | E57: {=INDEX(CPI_Data[#All], MATCH("Urban"&"2023"&"May",CPI_Data[[#All],[Sector]]&CPI_Data[[#All],[Year]]&CPI_Data[[#All],[Month]],0), MATCH('Q1 - CPI Contribution'!B57,CPI_Data[#Headers],0))} -> 211.9 | F57: {=INDEX(CPI_Data[#All], MATCH("Rural+Urban"&"2023"&"May",CPI_Data[[#All],[Sector]]&CPI_Data[[#All],[Year]]&CPI_Data[[#All],[Month]],0), MATCH('Q1 - CPI Contribution'!B57,CPI_Data[#Headers],0))} -> 218
B58: Non-alcoholic beverages | C58: Food | D58: {=INDEX(CPI_Data[#All], MATCH("Rural"&"2023"&"May",CPI_Data[[#All],[Sector]]&CPI_Data[[#All],[Year]]&CPI_Data[[#All],[Month]],0), MATCH('Q1 - CPI Contribution'!B58,CPI_Data[#Headers],0))} -> 178.7 | E58: {=INDEX(CPI_Data[#All], MATCH("Urban"&"2023"&"May",CPI_Data[[#All],[Sector]]&CPI_Data[[#All],[Year]]&CPI_Data[[#All],[Month]],0), MATCH('Q1 - CPI Contribution'!B58,CPI_Data[#Headers],0))} -> 165.9 | F58: {=INDEX(CPI_Data[#All], MATCH("Rural+Urban"&"2023"&"May",CPI_Data[[#All],[Sector]]&CPI_Data[[#All],[Year]]&CPI_Data[[#All],[Month]],0), MATCH('Q1 - CPI Contribution'!B58,CPI_Data[#Headers],0))} -> 173.4
B59: Prepared meals, snacks, sweets etc. | C59: Food | D59: {=INDEX(CPI_Data[#All], MATCH("Rural"&"2023"&"May",CPI_Data[[#All],[Sector]]&CPI_Data[[#All],[Year]]&CPI_Data[[#All],[Month]],0), MATCH('Q1 - CPI Contribution'!B59,CPI_Data[#Headers],0))} -> 191.1 | E59: {=INDEX(CPI_Data[#All], MATCH("Urban"&"2023"&"May",CPI_Data[[#All],[Sector]]&CPI_Data[[#All],[Year]]&CPI_Data[[#All],[Month]],0), MATCH('Q1 - CPI Contribution'!B59,CPI_Data[#Headers],0))} -> 197.7 | F59: {=INDEX(CPI_Data[#All], MATCH("Rural+Urban"&"2023"&"May",CPI_Data[[#All],[Sector]]&CPI_Data[[#All],[Year]]&CPI_Data[[#All],[Month]],0), MATCH('Q1 - CPI Contribution'!B59,CPI_Data[#Headers],0))} -> 194.2
... B71: Miscellaneous | C71: Miscellaneous | D71: {=INDEX(CPI_Data[#All], MATCH("Rural"&"2023"&"May",CPI_Data[[#All],[Sector]]&CPI_Data[[#All],[Year]]&CPI_Data[[#All],[Month]],0), MATCH('Q1 - CPI Contribution'!B71,CPI_Data[#Headers],0))} -> 179.5 | E71: {=INDEX(CPI_Data[#All], MATCH("Urban"&"2023"&"May",CPI_Data[[#All],[Sector]]&CPI_Data[[#All],[Year]]&CPI_Data[[#All],[Month]],0), MATCH('Q1 - CPI Contribution'!B71,CPI_Data[#Headers],0))} -> 171.6 | F71: {=INDEX(CPI_Data[#All], MATCH("Rural+Urban"&"2023"&"May",CPI_Data[[#All],[Sector]]&CPI_Data[[#All],[Year]]&CPI_Data[[#All],[Month]],0), MATCH('Q1 - CPI Contribution'!B71,CPI_Data[#Headers],0))} -> 175.7

Sheet Q2 - YoY Inflation
Q16: Year | R16: CPI Index | S16: Inflation
Q17: 42491 | R17: {=INDEX(CPI_Data[General index], MATCH(1, (CPI_Data[Sector]="Rural+Urban")*(CPI_Data[Date]=Q17), 0))} -> 128.6
Q18: 42856 | R18: {=INDEX(CPI_Data[General index], MATCH(1, (CPI_Data[Sector]="Rural+Urban")*(CPI_Data[Date]=Q18), 0))} -> 131.4 | S18: =(R18-R17)/R17 -> 0.021772939
Q19: 43221 | R19: {=INDEX(CPI_Data[General index], MATCH(1, (CPI_Data[Sector]="Rural+Urban")*(CPI_Data[Date]=Q19), 0))} -> 137.8 | S19: =(R19-R18)/R18 -> 0.04870624
Q20: 43586 | R20: {=INDEX(CPI_Data[General index], MATCH(1, (CPI_Data[Sector]="Rural+Urban")*(CPI_Data[Date]=Q20), 0))} -> 142 | S20: =(R20-R19)/R19 -> 0.030478955
Q21: 43952 | R21: {=INDEX(CPI_Data[General index], MATCH(1, (CPI_Data[Sector]="Rural+Urban")*(CPI_Data[Date]=Q21), 0))} -> 150.9 | S21: =(R21-R20)/R20 -> 0.062676056
Q22: 44317 | R22: {=INDEX(CPI_Data[General index], MATCH(1, (CPI_Data[Sector]="Rural+Urban")*(CPI_Data[Date]=Q22), 0))} -> 160.4 | S22: =(R22-R21)/R21 -> 0.0629556
Q23: 44682 | R23: {=INDEX(CPI_Data[General index], MATCH(1, (CPI_Data[Sector]="Rural+Urban")*(CPI_Data[Date]=Q23), 0))} -> 171.7 | S23: =(R23-R22)/R22 -> 0.070448878
Q24: 45047 | R24: {=INDEX(CPI_Data[General index], MATCH(1, (CPI_Data[Sector]="Rural+Urban")*(CPI_Data[Date]=Q24), 0))} -> 179.1 | S24: =(R24-R23)/R23 -> 0.043098427

Sheet Q3 - Food Inflation
K32: Date | L32: Rural | M32: Inflation (R) | N32: Urban | O32: Inflation (U) | P32: Rural+Urban | Q32: Inflation (R+U)
K33: 44682 | L33: =AVERAGE( SUMIFS(CPI_Data[Cereals and products],CPI_Data[Sector],L$32,CPI_Data[Date],$K33), SUMIFS(CPI_Data[Meat and fish],CPI_Data[Sector],L$32,CPI_Data[Date],$K33), SUMIFS(CPI_Data[Egg],CPI_Data[Sector],L$32,CPI_Data[Date],$K33), SUMIFS(CPI_Data[Milk and products],CPI_Data[Sector],L$32,CPI_Data[Date],$K33), SUMIFS(CPI_Data[Oils and fats],CPI_Data[Sector],L$32,CPI_Data[Date],$K33), SUMIFS(CPI_Data[Fruits],CPI_Data[Sector],L$32,CPI_Data[Date],$K33), SUMIFS(CPI_Data[Vegetables],CPI_Data[Sector],L$32,CPI_Data[Date],$K33), SUMIFS(CPI_Data[Pulses and products],CPI_Data[Sector],L$32,CPI_Data[Date],$K33), SUMIFS(CPI_Data[Sugar and Confectionery],CPI_Data[Sector],L$32,CPI_Data[Date],$K33), SUMIFS(CPI_Data[Spices],CPI_Data[Sector],L$32,CPI_Data[Date],$K33), SUMIFS(CPI_Data[Non-alcoholic beverages],CPI_Data[Sector],L$32,CPI_Data[Date],$K33), SUMIFS(CPI_Data[Prepared meals, snacks, sweets etc.],CPI_Data[Sector],L$32,CPI_Data[Date],$K33) ) -> 171.33333 | N33: =AVERAGE( SUMIFS(CPI_Data[Cereals and products],CPI_Data[Sector],N$32,CPI_Data[Date],$K33), SUMIFS(CPI_Data[Meat and fish],CPI_Data[Sector],N$32,CPI_Data[Date],$K33), SUMIFS(CPI_Data[Egg],CPI_Data[Sector],N$32,CPI_Data[Date],$K33), SUMIFS(CPI_Data[Milk and products],CPI_Data[Sector],N$32,CPI_Data[Date],$K33), SUMIFS(CPI_Data[Oils and fats],CPI_Data[Sector],N$32,CPI_Data[Date],$K33), SUMIFS(CPI_Data[Fruits],CPI_Data[Sector],N$32,CPI_Data[Date],$K33), SUMIFS(CPI_Data[Vegetables],CPI_Data[Sector],N$32,CPI_Data[Date],$K33), SUMIFS(CPI_Data[Pulses and products],CPI_Data[Sector],N$32,CPI_Data[Date],$K33), SUMIFS(CPI_Data[Sugar and Confectionery],CPI_Data[Sector],N$32,CPI_Data[Date],$K33), SUMIFS(CPI_Data[Spices],CPI_Data[Sector],N$32,CPI_Data[Date],$K33), SUMIFS(CPI_Data[Non-alcoholic beverages],CPI_Data[Sector],N$32,CPI_Data[Date],$K33), SUMIFS(CPI_Data[Prepared meals, snacks, sweets etc.],CPI_Data[Sector],N$32,CPI_Data[Date],$K33) ) -> 173.725 | P33: =AVERAGE( SUMIFS(CPI_Data[Cereals and products],CPI_Data[Sector],P$32,CPI_Data[Date],$K33), SUMIFS(CPI_Data[Meat and fish],CPI_Data[Sector],P$32,CPI_Data[Date],$K33), SUMIFS(CPI_Data[Egg],CPI_Data[Sector],P$32,CPI_Data[Date],$K33), SUMIFS(CPI_Data[Milk and products],CPI_Data[Sector],P$32,CPI_Data[Date],$K33), SUMIFS(CPI_Data[Oils and fats],CPI_Data[Sector],P$32,CPI_Data[Date],$K33), SUMIFS(CPI_Data[Fruits],CPI_Data[Sector],P$32,CPI_Data[Date],$K33), SUMIFS(CPI_Data[Vegetables],CPI_Data[Sector],P$32,CPI_Data[Date],$K33), SUMIFS(CPI_Data[Pulses and products],CPI_Data[Sector],P$32,CPI_Data[Date],$K33), SUMIFS(CPI_Data[Sugar and Confectionery],CPI_Data[Sector],P$32,CPI_Data[Date],$K33), SUMIFS(CPI_Data[Spices],CPI_Data[Sector],P$32,CPI_Data[Date],$K33), SUMIFS(CPI_Data[Non-alcoholic beverages],CPI_Data[Sector],P$32,CPI_Data[Date],$K33), SUMIFS(CPI_Data[Prepared meals, snacks, sweets etc.],CPI_Data[Sector],P$32,CPI_Data[Date],$K33) ) -> 172.13333
K34: 44713 | L34: =AVERAGE( SUMIFS(CPI_Data[Cereals and products],CPI_Data[Sector],L$32,CPI_Data[Date],$K34), SUMIFS(CPI_Data[Meat and fish],CPI_Data[Sector],L$32,CPI_Data[Date],$K34), SUMIFS(CPI_Data[Egg],CPI_Data[Sector],L$32,CPI_Data[Date],$K34), SUMIFS(CPI_Data[Milk and products],CPI_Data[Sector],L$32,CPI_Data[Date],$K34), SUMIFS(CPI_Data[Oils and fats],CPI_Data[Sector],L$32,CPI_Data[Date],$K34), SUMIFS(CPI_Data[Fruits],CPI_Data[Sector],L$32,CPI_Data[Date],$K34), SUMIFS(CPI_Data[Vegetables],CPI_Data[Sector],L$32,CPI_Data[Date],$K34), SUMIFS(CPI_Data[Pulses and products],CPI_Data[Sector],L$32,CPI_Data[Date],$K34), SUMIFS(CPI_Data[Sugar and Confectionery],CPI_Data[Sector],L$32,CPI_Data[Date],$K34), SUMIFS(CPI_Data[Spices],CPI_Data[Sector],L$32,CPI_Data[Date],$K34), SUMIFS(CPI_Data[Non-alcoholic beverages],CPI_Data[Sector],L$32,CPI_Data[Date],$K34), SUMIFS(CPI_Data[Prepared meals, snacks, sweets etc.],CPI_Data[Sector],L$32,CPI_Data[Date],$K34) ) -> 172.99167 | M34: =(L34-L33)/L33 -> 0.0096789883 | N34: =AVERAGE( SUMIFS(CPI_Data[Cereals and products],CPI_Data[Sector],N$32,CPI_Data[Date],$K34), SUMIFS(CPI_Data[Meat and fish],CPI_Data[Sector],N$32,CPI_Data[Date],$K34), SUMIFS(CPI_Data[Egg],CPI_Data[Sector],N$32,CPI_Data[Date],$K34), SUMIFS(CPI_Data[Milk and products],CPI_Data[Sector],N$32,CPI_Data[Date],$K34), SUMIFS(CPI_Data[Oils and fats],CPI_Data[Sector],N$32,CPI_Data[Date],$K34), SUMIFS(CPI_Data[Fruits],CPI_Data[Sector],N$32,CPI_Data[Date],$K34), SUMIFS(CPI_Data[Vegetables],CPI_Data[Sector],N$32,CPI_Data[Date],$K34), SUMIFS(CPI_Data[Pulses and products],CPI_Data[Sector],N$32,CPI_Data[Date],$K34), SUMIFS(CPI_Data[Sugar and Confectionery],CPI_Data[Sector],N$32,CPI_Data[Date],$K34), SUMIFS(CPI_Data[Spices],CPI_Data[Sector],N$32,CPI_Data[Date],$K34), SUMIFS(CPI_Data[Non-alcoholic beverages],CPI_Data[Sector],N$32,CPI_Data[Date],$K34), SUMIFS(CPI_Data[Prepared meals, snacks, sweets etc.],CPI_Data[Sector],N$32,CPI_Data[Date],$K34) ) -> 175.68333 | O34: =(N34-N33)/N33 -> 0.011272605 | P34: =AVERAGE( SUMIFS(CPI_Data[Cereals and products],CPI_Data[Sector],P$32,CPI_Data[Date],$K34), SUMIFS(CPI_Data[Meat and fish],CPI_Data[Sector],P$32,CPI_Data[Date],$K34), SUMIFS(CPI_Data[Egg],CPI_Data[Sector],P$32,CPI_Data[Date],$K34), SUMIFS(CPI_Data[Milk and products],CPI_Data[Sector],P$32,CPI_Data[Date],$K34), SUMIFS(CPI_Data[Oils and fats],CPI_Data[Sector],P$32,CPI_Data[Date],$K34), SUMIFS(CPI_Data[Fruits],CPI_Data[Sector],P$32,CPI_Data[Date],$K34), SUMIFS(CPI_Data[Vegetables],CPI_Data[Sector],P$32,CPI_Data[Date],$K34), SUMIFS(CPI_Data[Pulses and products],CPI_Data[Sector],P$32,CPI_Data[Date],$K34), SUMIFS(CPI_Data[Sugar and Confectionery],CPI_Data[Sector],P$32,CPI_Data[Date],$K34), SUMIFS(CPI_Data[Spices],CPI_Data[Sector],P$32,CPI_Data[Date],$K34), SUMIFS(CPI_Data[Non-alcoholic beverages],CPI_Data[Sector],P$32,CPI_Data[Date],$K34), SUMIFS(CPI_Data[Prepared meals, snacks, sweets etc.],CPI_Data[Sector],P$32,CPI_Data[Date],$K34) ) -> 173.91667 | Q34: =(P34-P33)/P33 -> 0.010360186
K35: 44743 | L35: =AVERAGE( SUMIFS(CPI_Data[Cereals and products],CPI_Data[Sector],L$32,CPI_Data[Date],$K35), SUMIFS(CPI_Data[Meat and fish],CPI_Data[Sector],L$32,CPI_Data[Date],$K35), SUMIFS(CPI_Data[Egg],CPI_Data[Sector],L$32,CPI_Data[Date],$K35), SUMIFS(CPI_Data[Milk and products],CPI_Data[Sector],L$32,CPI_Data[Date],$K35), SUMIFS(CPI_Data[Oils and fats],CPI_Data[Sector],L$32,CPI_Data[Date],$K35), SUMIFS(CPI_Data[Fruits],CPI_Data[Sector],L$32,CPI_Data[Date],$K35), SUMIFS(CPI_Data[Vegetables],CPI_Data[Sector],L$32,CPI_Data[Date],$K35), SUMIFS(CPI_Data[Pulses and products],CPI_Data[Sector],L$32,CPI_Data[Date],$K35), SUMIFS(CPI_Data[Sugar and Confectionery],CPI_Data[Sector],L$32,CPI_Data[Date],$K35), SUMIFS(CPI_Data[Spices],CPI_Data[Sector],L$32,CPI_Data[Date],$K35), SUMIFS(CPI_Data[Non-alcoholic beverages],CPI_Data[Sector],L$32,CPI_Data[Date],$K35), SUMIFS(CPI_Data[Prepared meals, snacks, sweets etc.],CPI_Data[Sector],L$32,CPI_Data[Date],$K35) ) -> 173.33333 | M35: =(L35-L34)/L34 -> 0.001975047 | N35: =AVERAGE( SUMIFS(CPI_Data[Cereals and products],CPI_Data[Sector],N$32,CPI_Data[Date],$K35), SUMIFS(CPI_Data[Meat and fish],CPI_Data[Sector],N$32,CPI_Data[Date],$K35), SUMIFS(CPI_Data[Egg],CPI_Data[Sector],N$32,CPI_Data[Date],$K35), SUMIFS(CPI_Data[Milk and products],CPI_Data[Sector],N$32,CPI_Data[Date],$K35), SUMIFS(CPI_Data[Oils and fats],CPI_Data[Sector],N$32,CPI_Data[Date],$K35), SUMIFS(CPI_Data[Fruits],CPI_Data[Sector],N$32,CPI_Data[Date],$K35), SUMIFS(CPI_Data[Vegetables],CPI_Data[Sector],N$32,CPI_Data[Date],$K35), SUMIFS(CPI_Data[Pulses and products],CPI_Data[Sector],N$32,CPI_Data[Date],$K35), SUMIFS(CPI_Data[Sugar and Confectionery],CPI_Data[Sector],N$32,CPI_Data[Date],$K35), SUMIFS(CPI_Data[Spices],CPI_Data[Sector],N$32,CPI_Data[Date],$K35), SUMIFS(CPI_Data[Non-alcoholic beverages],CPI_Data[Sector],N$32,CPI_Data[Date],$K35), SUMIFS(CPI_Data[Prepared meals, snacks, sweets etc.],CPI_Data[Sector],N$32,CPI_Data[Date],$K35) ) -> 176.01667 | O35: =(N35-N34)/N34 -> 0.0018973532 | P35: =AVERAGE( SUMIFS(CPI_Data[Cereals and products],CPI_Data[Sector],P$32,CPI_Data[Date],$K35), SUMIFS(CPI_Data[Meat and fish],CPI_Data[Sector],P$32,CPI_Data[Date],$K35), SUMIFS(CPI_Data[Egg],CPI_Data[Sector],P$32,CPI_Data[Date],$K35), SUMIFS(CPI_Data[Milk and products],CPI_Data[Sector],P$32,CPI_Data[Date],$K35), SUMIFS(CPI_Data[Oils and fats],CPI_Data[Sector],P$32,CPI_Data[Date],$K35), SUMIFS(CPI_Data[Fruits],CPI_Data[Sector],P$32,CPI_Data[Date],$K35), SUMIFS(CPI_Data[Vegetables],CPI_Data[Sector],P$32,CPI_Data[Date],$K35), SUMIFS(CPI_Data[Pulses and products],CPI_Data[Sector],P$32,CPI_Data[Date],$K35), SUMIFS(CPI_Data[Sugar and Confectionery],CPI_Data[Sector],P$32,CPI_Data[Date],$K35), SUMIFS(CPI_Data[Spices],CPI_Data[Sector],P$32,CPI_Data[Date],$K35), SUMIFS(CPI_Data[Non-alcoholic beverages],CPI_Data[Sector],P$32,CPI_Data[Date],$K35), SUMIFS(CPI_Data[Prepared meals, snacks, sweets etc.],CPI_Data[Sector],P$32,CPI_Data[Date],$K35) ) -> 174.275 | Q35: =(P35-P34)/P34 -> 0.0020603737
K36: 44774 | L36: =AVERAGE( SUMIFS(CPI_Data[Cereals and products],CPI_Data[Sector],L$32,CPI_Data[Date],$K36), SUMIFS(CPI_Data[Meat and fish],CPI_Data[Sector],L$32,CPI_Data[Date],$K36), SUMIFS(CPI_Data[Egg],CPI_Data[Sector],L$32,CPI_Data[Date],$K36), SUMIFS(CPI_Data[Milk and products],CPI_Data[Sector],L$32,CPI_Data[Date],$K36), SUMIFS(CPI_Data[Oils and fats],CPI_Data[Sector],L$32,CPI_Data[Date],$K36), SUMIFS(CPI_Data[Fruits],CPI_Data[Sector],L$32,CPI_Data[Date],$K36), SUMIFS(CPI_Data[Vegetables],CPI_Data[Sector],L$32,CPI_Data[Date],$K36), SUMIFS(CPI_Data[Pulses and products],CPI_Data[Sector],L$32,CPI_Data[Date],$K36), SUMIFS(CPI_Data[Sugar and Confectionery],CPI_Data[Sector],L$32,CPI_Data[Date],$K36), SUMIFS(CPI_Data[Spices],CPI_Data[Sector],L$32,CPI_Data[Date],$K36), SUMIFS(CPI_Data[Non-alcoholic beverages],CPI_Data[Sector],L$32,CPI_Data[Date],$K36), SUMIFS(CPI_Data[Prepared meals, snacks, sweets etc.],CPI_Data[Sector],L$32,CPI_Data[Date],$K36) ) -> 173.49167 | M36: =(L36-L35)/L35 -> 0.00091346154 | N36: =AVERAGE( SUMIFS(CPI_Data[Cereals and products],CPI_Data[Sector],N$32,CPI_Data[Date],$K36), SUMIFS(CPI_Data[Meat and fish],CPI_Data[Sector],N$32,CPI_Data[Date],$K36), SUMIFS(CPI_Data[Egg],CPI_Data[Sector],N$32,CPI_Data[Date],$K36), SUMIFS(CPI_Data[Milk and products],CPI_Data[Sector],N$32,CPI_Data[Date],$K36), SUMIFS(CPI_Data[Oils and fats],CPI_Data[Sector],N$32,CPI_Data[Date],$K36), SUMIFS(CPI_Data[Fruits],CPI_Data[Sector],N$32,CPI_Data[Date],$K36), SUMIFS(CPI_Data[Vegetables],CPI_Data[Sector],N$32,CPI_Data[Date],$K36), SUMIFS(CPI_Data[Pulses and products],CPI_Data[Sector],N$32,CPI_Data[Date],$K36), SUMIFS(CPI_Data[Sugar and Confectionery],CPI_Data[Sector],N$32,CPI_Data[Date],$K36), SUMIFS(CPI_Data[Spices],CPI_Data[Sector],N$32,CPI_Data[Date],$K36), SUMIFS(CPI_Data[Non-alcoholic beverages],CPI_Data[Sector],N$32,CPI_Data[Date],$K36), SUMIFS(CPI_Data[Prepared meals, snacks, sweets etc.],CPI_Data[Sector],N$32,CPI_Data[Date],$K36) ) -> 176.10833 | O36: =(N36-N35)/N35 -> 0.00052078402 | P36: =AVERAGE( SUMIFS(CPI_Data[Cereals and products],CPI_Data[Sector],P$32,CPI_Data[Date],$K36), SUMIFS(CPI_Data[Meat and fish],CPI_Data[Sector],P$32,CPI_Data[Date],$K36), SUMIFS(CPI_Data[Egg],CPI_Data[Sector],P$32,CPI_Data[Date],$K36), SUMIFS(CPI_Data[Milk and products],CPI_Data[Sector],P$32,CPI_Data[Date],$K36), SUMIFS(CPI_Data[Oils and fats],CPI_Data[Sector],P$32,CPI_Data[Date],$K36), SUMIFS(CPI_Data[Fruits],CPI_Data[Sector],P$32,CPI_Data[Date],$K36), SUMIFS(CPI_Data[Vegetables],CPI_Data[Sector],P$32,CPI_Data[Date],$K36), SUMIFS(CPI_Data[Pulses and products],CPI_Data[Sector],P$32,CPI_Data[Date],$K36), SUMIFS(CPI_Data[Sugar and Confectionery],CPI_Data[Sector],P$32,CPI_Data[Date],$K36), SUMIFS(CPI_Data[Spices],CPI_Data[Sector],P$32,CPI_Data[Date],$K36), SUMIFS(CPI_Data[Non-alcoholic beverages],CPI_Data[Sector],P$32,CPI_Data[Date],$K36), SUMIFS(CPI_Data[Prepared meals, snacks, sweets etc.],CPI_Data[Sector],P$32,CPI_Data[Date],$K36) ) -> 174.40833 | Q36: =(P36-P35)/P35 -> 0.00076507436
K37: 44805 | L37: =AVERAGE( SUMIFS(CPI_Data[Cereals and products],CPI_Data[Sector],L$32,CPI_Data[Date],$K37), SUMIFS(CPI_Data[Meat and fish],CPI_Data[Sector],L$32,CPI_Data[Date],$K37), SUMIFS(CPI_Data[Egg],CPI_Data[Sector],L$32,CPI_Data[Date],$K37), SUMIFS(CPI_Data[Milk and products],CPI_Data[Sector],L$32,CPI_Data[Date],$K37), SUMIFS(CPI_Data[Oils and fats],CPI_Data[Sector],L$32,CPI_Data[Date],$K37), SUMIFS(CPI_Data[Fruits],CPI_Data[Sector],L$32,CPI_Data[Date],$K37), SUMIFS(CPI_Data[Vegetables],CPI_Data[Sector],L$32,CPI_Data[Date],$K37), SUMIFS(CPI_Data[Pulses and products],CPI_Data[Sector],L$32,CPI_Data[Date],$K37), SUMIFS(CPI_Data[Sugar and Confectionery],CPI_Data[Sector],L$32,CPI_Data[Date],$K37), SUMIFS(CPI_Data[Spices],CPI_Data[Sector],L$32,CPI_Data[Date],$K37), SUMIFS(CPI_Data[Non-alcoholic beverages],CPI_Data[Sector],L$32,CPI_Data[Date],$K37), SUMIFS(CPI_Data[Prepared meals, snacks, sweets etc.],CPI_Data[Sector],L$32,CPI_Data[Date],$K37) ) -> 174.35833 | M37: =(L37-L36)/L36 -> 0.0049954369 | N37: =AVERAGE( SUMIFS(CPI_Data[Cereals and products],CPI_Data[Sector],N$32,CPI_Data[Date],$K37), SUMIFS(CPI_Data[Meat and fish],CPI_Data[Sector],N$32,CPI_Data[Date],$K37), SUMIFS(CPI_Data[Egg],CPI_Data[Sector],N$32,CPI_Data[Date],$K37), SUMIFS(CPI_Data[Milk and products],CPI_Data[Sector],N$32,CPI_Data[Date],$K37), SUMIFS(CPI_Data[Oils and fats],CPI_Data[Sector],N$32,CPI_Data[Date],$K37), SUMIFS(CPI_Data[Fruits],CPI_Data[Sector],N$32,CPI_Data[Date],$K37), SUMIFS(CPI_Data[Vegetables],CPI_Data[Sector],N$32,CPI_Data[Date],$K37), SUMIFS(CPI_Data[Pulses and products],CPI_Data[Sector],N$32,CPI_Data[Date],$K37), SUMIFS(CPI_Data[Sugar and Confectionery],CPI_Data[Sector],N$32,CPI_Data[Date],$K37), SUMIFS(CPI_Data[Spices],CPI_Data[Sector],N$32,CPI_Data[Date],$K37), SUMIFS(CPI_Data[Non-alcoholic beverages],CPI_Data[Sector],N$32,CPI_Data[Date],$K37), SUMIFS(CPI_Data[Prepared meals, snacks, sweets etc.],CPI_Data[Sector],N$32,CPI_Data[Date],$K37) ) -> 177.05 | O37: =(N37-N36)/N36 -> 0.0053470875 | P37: =AVERAGE( SUMIFS(CPI_Data[Cereals and products],CPI_Data[Sector],P$32,CPI_Data[Date],$K37), SUMIFS(CPI_Data[Meat and fish],CPI_Data[Sector],P$32,CPI_Data[Date],$K37), SUMIFS(CPI_Data[Egg],CPI_Data[Sector],P$32,CPI_Data[Date],$K37), SUMIFS(CPI_Data[Milk and products],CPI_Data[Sector],P$32,CPI_Data[Date],$K37), SUMIFS(CPI_Data[Oils and fats],CPI_Data[Sector],P$32,CPI_Data[Date],$K37), SUMIFS(CPI_Data[Fruits],CPI_Data[Sector],P$32,CPI_Data[Date],$K37), SUMIFS(CPI_Data[Vegetables],CPI_Data[Sector],P$32,CPI_Data[Date],$K37), SUMIFS(CPI_Data[Pulses and products],CPI_Data[Sector],P$32,CPI_Data[Date],$K37), SUMIFS(CPI_Data[Sugar and Confectionery],CPI_Data[Sector],P$32,CPI_Data[Date],$K37), SUMIFS(CPI_Data[Spices],CPI_Data[Sector],P$32,CPI_Data[Date],$K37), SUMIFS(CPI_Data[Non-alcoholic beverages],CPI_Data[Sector],P$32,CPI_Data[Date],$K37), SUMIFS(CPI_Data[Prepared meals, snacks, sweets etc.],CPI_Data[Sector],P$32,CPI_Data[Date],$K37) ) -> 175.25833 | Q37: =(P37-P36)/P36 -> 0.0048736203
K38: 44835 | L38: =AVERAGE( SUMIFS(CPI_Data[Cereals and products],CPI_Data[Sector],L$32,CPI_Data[Date],$K38), SUMIFS(CPI_Data[Meat and fish],CPI_Data[Sector],L$32,CPI_Data[Date],$K38), SUMIFS(CPI_Data[Egg],CPI_Data[Sector],L$32,CPI_Data[Date],$K38), SUMIFS(CPI_Data[Milk and products],CPI_Data[Sector],L$32,CPI_Data[Date],$K38), SUMIFS(CPI_Data[Oils and fats],CPI_Data[Sector],L$32,CPI_Data[Date],$K38), SUMIFS(CPI_Data[Fruits],CPI_Data[Sector],L$32,CPI_Data[Date],$K38), SUMIFS(CPI_Data[Vegetables],CPI_Data[Sector],L$32,CPI_Data[Date],$K38), SUMIFS(CPI_Data[Pulses and products],CPI_Data[Sector],L$32,CPI_Data[Date],$K38), SUMIFS(CPI_Data[Sugar and Confectionery],CPI_Data[Sector],L$32,CPI_Data[Date],$K38), SUMIFS(CPI_Data[Spices],CPI_Data[Sector],L$32,CPI_Data[Date],$K38), SUMIFS(CPI_Data[Non-alcoholic beverages],CPI_Data[Sector],L$32,CPI_Data[Date],$K38), SUMIFS(CPI_Data[Prepared meals, snacks, sweets etc.],CPI_Data[Sector],L$32,CPI_Data[Date],$K38) ) -> 175.59167 | M38: =(L38-L37)/L37 -> 0.0070735554 | N38: =AVERAGE( SUMIFS(CPI_Data[Cereals and products],CPI_Data[Sector],N$32,CPI_Data[Date],$K38), SUMIFS(CPI_Data[Meat and fish],CPI_Data[Sector],N$32,CPI_Data[Date],$K38), SUMIFS(CPI_Data[Egg],CPI_Data[Sector],N$32,CPI_Data[Date],$K38), SUMIFS(CPI_Data[Milk and products],CPI_Data[Sector],N$32,CPI_Data[Date],$K38), SUMIFS(CPI_Data[Oils and fats],CPI_Data[Sector],N$32,CPI_Data[Date],$K38), SUMIFS(CPI_Data[Fruits],CPI_Data[Sector],N$32,CPI_Data[Date],$K38), SUMIFS(CPI_Data[Vegetables],CPI_Data[Sector],N$32,CPI_Data[Date],$K38), SUMIFS(CPI_Data[Pulses and products],CPI_Data[Sector],N$32,CPI_Data[Date],$K38), SUMIFS(CPI_Data[Sugar and Confectionery],CPI_Data[Sector],N$32,CPI_Data[Date],$K38), SUMIFS(CPI_Data[Spices],CPI_Data[Sector],N$32,CPI_Data[Date],$K38), SUMIFS(CPI_Data[Non-alcoholic beverages],CPI_Data[Sector],N$32,CPI_Data[Date],$K38), SUMIFS(CPI_Data[Prepared meals, snacks, sweets etc.],CPI_Data[Sector],N$32,CPI_Data[Date],$K38) ) -> 178.25 | O38: =(N38-N37)/N37 -> 0.0067777464 | P38: =AVERAGE( SUMIFS(CPI_Data[Cereals and products],CPI_Data[Sector],P$32,CPI_Data[Date],$K38), SUMIFS(CPI_Data[Meat and fish],CPI_Data[Sector],P$32,CPI_Data[Date],$K38), SUMIFS(CPI_Data[Egg],CPI_Data[Sector],P$32,CPI_Data[Date],$K38), SUMIFS(CPI_Data[Milk and products],CPI_Data[Sector],P$32,CPI_Data[Date],$K38), SUMIFS(CPI_Data[Oils and fats],CPI_Data[Sector],P$32,CPI_Data[Date],$K38), SUMIFS(CPI_Data[Fruits],CPI_Data[Sector],P$32,CPI_Data[Date],$K38), SUMIFS(CPI_Data[Vegetables],CPI_Data[Sector],P$32,CPI_Data[Date],$K38), SUMIFS(CPI_Data[Pulses and products],CPI_Data[Sector],P$32,CPI_Data[Date],$K38), SUMIFS(CPI_Data[Sugar and Confectionery],CPI_Data[Sector],P$32,CPI_Data[Date],$K38), SUMIFS(CPI_Data[Spices],CPI_Data[Sector],P$32,CPI_Data[Date],$K38), SUMIFS(CPI_Data[Non-alcoholic beverages],CPI_Data[Sector],P$32,CPI_Data[Date],$K38), SUMIFS(CPI_Data[Prepared meals, snacks, sweets etc.],CPI_Data[Sector],P$32,CPI_Data[Date],$K38) ) -> 176.475 | Q38: =(P38-P37)/P37 -> 0.006942133
K39: 44866 | L39: =AVERAGE( SUMIFS(CPI_Data[Cereals and products],CPI_Data[Sector],L$32,CPI_Data[Date],$K39), SUMIFS(CPI_Data[Meat and fish],CPI_Data[Sector],L$32,CPI_Data[Date],$K39), SUMIFS(CPI_Data[Egg],CPI_Data[Sector],L$32,CPI_Data[Date],$K39), SUMIFS(CPI_Data[Milk and products],CPI_Data[Sector],L$32,CPI_Data[Date],$K39), SUMIFS(CPI_Data[Oils and fats],CPI_Data[Sector],L$32,CPI_Data[Date],$K39), SUMIFS(CPI_Data[Fruits],CPI_Data[Sector],L$32,CPI_Data[Date],$K39), SUMIFS(CPI_Data[Vegetables],CPI_Data[Sector],L$32,CPI_Data[Date],$K39), SUMIFS(CPI_Data[Pulses and products],CPI_Data[Sector],L$32,CPI_Data[Date],$K39), SUMIFS(CPI_Data[Sugar and Confectionery],CPI_Data[Sector],L$32,CPI_Data[Date],$K39), SUMIFS(CPI_Data[Spices],CPI_Data[Sector],L$32,CPI_Data[Date],$K39), SUMIFS(CPI_Data[Non-alcoholic beverages],CPI_Data[Sector],L$32,CPI_Data[Date],$K39), SUMIFS(CPI_Data[Prepared meals, snacks, sweets etc.],CPI_Data[Sector],L$32,CPI_Data[Date],$K39) ) -> 175.925 | M39: =(L39-L38)/L38 -> 0.0018983437 | N39: =AVERAGE( SUMIFS(CPI_Data[Cereals and products],CPI_Data[Sector],N$32,CPI_Data[Date],$K39), SUMIFS(CPI_Data[Meat and fish],CPI_Data[Sector],N$32,CPI_Data[Date],$K39), SUMIFS(CPI_Data[Egg],CPI_Data[Sector],N$32,CPI_Data[Date],$K39), SUMIFS(CPI_Data[Milk and products],CPI_Data[Sector],N$32,CPI_Data[Date],$K39), SUMIFS(CPI_Data[Oils and fats],CPI_Data[Sector],N$32,CPI_Data[Date],$K39), SUMIFS(CPI_Data[Fruits],CPI_Data[Sector],N$32,CPI_Data[Date],$K39), SUMIFS(CPI_Data[Vegetables],CPI_Data[Sector],N$32,CPI_Data[Date],$K39), SUMIFS(CPI_Data[Pulses and products],CPI_Data[Sector],N$32,CPI_Data[Date],$K39), SUMIFS(CPI_Data[Sugar and Confectionery],CPI_Data[Sector],N$32,CPI_Data[Date],$K39), SUMIFS(CPI_Data[Spices],CPI_Data[Sector],N$32,CPI_Data[Date],$K39), SUMIFS(CPI_Data[Non-alcoholic beverages],CPI_Data[Sector],N$32,CPI_Data[Date],$K39), SUMIFS(CPI_Data[Prepared meals, snacks, sweets etc.],CPI_Data[Sector],N$32,CPI_Data[Date],$K39) ) -> 177.75833 | O39: =(N39-N38)/N38 -> -0.0027582983 | P39: =AVERAGE( SUMIFS(CPI_Data[Cereals and products],CPI_Data[Sector],P$32,CPI_Data[Date],$K39), SUMIFS(CPI_Data[Meat and fish],CPI_Data[Sector],P$32,CPI_Data[Date],$K39), SUMIFS(CPI_Data[Egg],CPI_Data[Sector],P$32,CPI_Data[Date],$K39), SUMIFS(CPI_Data[Milk and products],CPI_Data[Sector],P$32,CPI_Data[Date],$K39), SUMIFS(CPI_Data[Oils and fats],CPI_Data[Sector],P$32,CPI_Data[Date],$K39), SUMIFS(CPI_Data[Fruits],CPI_Data[Sector],P$32,CPI_Data[Date],$K39), SUMIFS(CPI_Data[Vegetables],CPI_Data[Sector],P$32,CPI_Data[Date],$K39), SUMIFS(CPI_Data[Pulses and products],CPI_Data[Sector],P$32,CPI_Data[Date],$K39), SUMIFS(CPI_Data[Sugar and Confectionery],CPI_Data[Sector],P$32,CPI_Data[Date],$K39), SUMIFS(CPI_Data[Spices],CPI_Data[Sector],P$32,CPI_Data[Date],$K39), SUMIFS(CPI_Data[Non-alcoholic beverages],CPI_Data[Sector],P$32,CPI_Data[Date],$K39), SUMIFS(CPI_Data[Prepared meals, snacks, sweets etc.],CPI_Data[Sector],P$32,CPI_Data[Date],$K39) ) -> 176.54167 | Q39: =(P39-P38)/P38 -> 0.00037776833
K40: 44896 | L40: =AVERAGE( SUMIFS(CPI_Data[Cereals and products],CPI_Data[Sector],L$32,CPI_Data[Date],$K40), SUMIFS(CPI_Data[Meat and fish],CPI_Data[Sector],L$32,CPI_Data[Date],$K40), SUMIFS(CPI_Data[Egg],CPI_Data[Sector],L$32,CPI_Data[Date],$K40), SUMIFS(CPI_Data[Milk and products],CPI_Data[Sector],L$32,CPI_Data[Date],$K40), SUMIFS(CPI_Data[Oils and fats],CPI_Data[Sector],L$32,CPI_Data[Date],$K40), SUMIFS(CPI_Data[Fruits],CPI_Data[Sector],L$32,CPI_Data[Date],$K40), SUMIFS(CPI_Data[Vegetables],CPI_Data[Sector],L$32,CPI_Data[Date],$K40), SUMIFS(CPI_Data[Pulses and products],CPI_Data[Sector],L$32,CPI_Data[Date],$K40), SUMIFS(CPI_Data[Sugar and Confectionery],CPI_Data[Sector],L$32,CPI_Data[Date],$K40), SUMIFS(CPI_Data[Spices],CPI_Data[Sector],L$32,CPI_Data[Date],$K40), SUMIFS(CPI_Data[Non-alcoholic beverages],CPI_Data[Sector],L$32,CPI_Data[Date],$K40), SUMIFS(CPI_Data[Prepared meals, snacks, sweets etc.],CPI_Data[Sector],L$32,CPI_Data[Date],$K40) ) -> 175.225 | M40: =(L40-L39)/L39 -> -0.0039789683 | N40: =AVERAGE( SUMIFS(CPI_Data[Cereals and products],CPI_Data[Sector],N$32,CPI_Data[Date],$K40), SUMIFS(CPI_Data[Meat and fish],CPI_Data[Sector],N$32,CPI_Data[Date],$K40), SUMIFS(CPI_Data[Egg],CPI_Data[Sector],N$32,CPI_Data[Date],$K40), SUMIFS(CPI_Data[Milk and products],CPI_Data[Sector],N$32,CPI_Data[Date],$K40), SUMIFS(CPI_Data[Oils and fats],CPI_Data[Sector],N$32,CPI_Data[Date],$K40), SUMIFS(CPI_Data[Fruits],CPI_Data[Sector],N$32,CPI_Data[Date],$K40), SUMIFS(CPI_Data[Vegetables],CPI_Data[Sector],N$32,CPI_Data[Date],$K40), SUMIFS(CPI_Data[Pulses and products],CPI_Data[Sector],N$32,CPI_Data[Date],$K40), SUMIFS(CPI_Data[Sugar and Confectionery],CPI_Data[Sector],N$32,CPI_Data[Date],$K40), SUMIFS(CPI_Data[Spices],CPI_Data[Sector],N$32,CPI_Data[Date],$K40), SUMIFS(CPI_Data[Non-alcoholic beverages],CPI_Data[Sector],N$32,CPI_Data[Date],$K40), SUMIFS(CPI_Data[Prepared meals, snacks, sweets etc.],CPI_Data[Sector],N$32,CPI_Data[Date],$K40) ) -> 176.43333 | O40: =(N40-N39)/N39 -> -0.0074539403 | P40: =AVERAGE( SUMIFS(CPI_Data[Cereals and products],CPI_Data[Sector],P$32,CPI_Data[Date],$K40), SUMIFS(CPI_Data[Meat and fish],CPI_Data[Sector],P$32,CPI_Data[Date],$K40), SUMIFS(CPI_Data[Egg],CPI_Data[Sector],P$32,CPI_Data[Date],$K40), SUMIFS(CPI_Data[Milk and products],CPI_Data[Sector],P$32,CPI_Data[Date],$K40), SUMIFS(CPI_Data[Oils and fats],CPI_Data[Sector],P$32,CPI_Data[Date],$K40), SUMIFS(CPI_Data[Fruits],CPI_Data[Sector],P$32,CPI_Data[Date],$K40), SUMIFS(CPI_Data[Vegetables],CPI_Data[Sector],P$32,CPI_Data[Date],$K40), SUMIFS(CPI_Data[Pulses and products],CPI_Data[Sector],P$32,CPI_Data[Date],$K40), SUMIFS(CPI_Data[Sugar and Confectionery],CPI_Data[Sector],P$32,CPI_Data[Date],$K40), SUMIFS(CPI_Data[Spices],CPI_Data[Sector],P$32,CPI_Data[Date],$K40), SUMIFS(CPI_Data[Non-alcoholic beverages],CPI_Data[Sector],P$32,CPI_Data[Date],$K40), SUMIFS(CPI_Data[Prepared meals, snacks, sweets etc.],CPI_Data[Sector],P$32,CPI_Data[Date],$K40) ) -> 175.625 | Q40: =(P40-P39)/P39 -> -0.0051923531
K41: 44927 | L41: =AVERAGE( SUMIFS(CPI_Data[Cereals and products],CPI_Data[Sector],L$32,CPI_Data[Date],$K41), SUMIFS(CPI_Data[Meat and fish],CPI_Data[Sector],L$32,CPI_Data[Date],$K41), SUMIFS(CPI_Data[Egg],CPI_Data[Sector],L$32,CPI_Data[Date],$K41), SUMIFS(CPI_Data[Milk and products],CPI_Data[Sector],L$32,CPI_Data[Date],$K41), SUMIFS(CPI_Data[Oils and fats],CPI_Data[Sector],L$32,CPI_Data[Date],$K41), SUMIFS(CPI_Data[Fruits],CPI_Data[Sector],L$32,CPI_Data[Date],$K41), SUMIFS(CPI_Data[Vegetables],CPI_Data[Sector],L$32,CPI_Data[Date],$K41), SUMIFS(CPI_Data[Pulses and products],CPI_Data[Sector],L$32,CPI_Data[Date],$K41), SUMIFS(CPI_Data[Sugar and Confectionery],CPI_Data[Sector],L$32,CPI_Data[Date],$K41), SUMIFS(CPI_Data[Spices],CPI_Data[Sector],L$32,CPI_Data[Date],$K41), SUMIFS(CPI_Data[Non-alcoholic beverages],CPI_Data[Sector],L$32,CPI_Data[Date],$K41), SUMIFS(CPI_Data[Prepared meals, snacks, sweets etc.],CPI_Data[Sector],L$32,CPI_Data[Date],$K41) ) -> 175.68333 | M41: =(L41-L40)/L40 -> 0.0026156846 | N41: =AVERAGE( SUMIFS(CPI_Data[Cereals and products],CPI_Data[Sector],N$32,CPI_Data[Date],$K41), SUMIFS(CPI_Data[Meat and fish],CPI_Data[Sector],N$32,CPI_Data[Date],$K41), SUMIFS(CPI_Data[Egg],CPI_Data[Sector],N$32,CPI_Data[Date],$K41), SUMIFS(CPI_Data[Milk and products],CPI_Data[Sector],N$32,CPI_Data[Date],$K41), SUMIFS(CPI_Data[Oils and fats],CPI_Data[Sector],N$32,CPI_Data[Date],$K41), SUMIFS(CPI_Data[Fruits],CPI_Data[Sector],N$32,CPI_Data[Date],$K41), SUMIFS(CPI_Data[Vegetables],CPI_Data[Sector],N$32,CPI_Data[Date],$K41), SUMIFS(CPI_Data[Pulses and products],CPI_Data[Sector],N$32,CPI_Data[Date],$K41), SUMIFS(CPI_Data[Sugar and Confectionery],CPI_Data[Sector],N$32,CPI_Data[Date],$K41), SUMIFS(CPI_Data[Spices],CPI_Data[Sector],N$32,CPI_Data[Date],$K41), SUMIFS(CPI_Data[Non-alcoholic beverages],CPI_Data[Sector],N$32,CPI_Data[Date],$K41), SUMIFS(CPI_Data[Prepared meals, snacks, sweets etc.],CPI_Data[Sector],N$32,CPI_Data[Date],$K41) ) -> 177.55833 | O41: =(N41-N40)/N40 -> 0.0063763461 | P41: =AVERAGE( SUMIFS(CPI_Data[Cereals and products],CPI_Data[Sector],P$32,CPI_Data[Date],$K41), SUMIFS(CPI_Data[Meat and fish],CPI_Data[Sector],P$32,CPI_Data[Date],$K41), SUMIFS(CPI_Data[Egg],CPI_Data[Sector],P$32,CPI_Data[Date],$K41), SUMIFS(CPI_Data[Milk and products],CPI_Data[Sector],P$32,CPI_Data[Date],$K41), SUMIFS(CPI_Data[Oils and fats],CPI_Data[Sector],P$32,CPI_Data[Date],$K41), SUMIFS(CPI_Data[Fruits],CPI_Data[Sector],P$32,CPI_Data[Date],$K41), SUMIFS(CPI_Data[Vegetables],CPI_Data[Sector],P$32,CPI_Data[Date],$K41), SUMIFS(CPI_Data[Pulses and products],CPI_Data[Sector],P$32,CPI_Data[Date],$K41), SUMIFS(CPI_Data[Sugar and Confectionery],CPI_Data[Sector],P$32,CPI_Data[Date],$K41), SUMIFS(CPI_Data[Spices],CPI_Data[Sector],P$32,CPI_Data[Date],$K41), SUMIFS(CPI_Data[Non-alcoholic beverages],CPI_Data[Sector],P$32,CPI_Data[Date],$K41), SUMIFS(CPI_Data[Prepared meals, snacks, sweets etc.],CPI_Data[Sector],P$32,CPI_Data[Date],$K41) ) -> 176.33333 | Q41: =(P41-P40)/P40 -> 0.0040332147
K42: 44958 | L42: =AVERAGE( SUMIFS(CPI_Data[Cereals and products],CPI_Data[Sector],L$32,CPI_Data[Date],$K42), SUMIFS(CPI_Data[Meat and fish],CPI_Data[Sector],L$32,CPI_Data[Date],$K42), SUMIFS(CPI_Data[Egg],CPI_Data[Sector],L$32,CPI_Data[Date],$K42), SUMIFS(CPI_Data[Milk and products],CPI_Data[Sector],L$32,CPI_Data[Date],$K42), SUMIFS(CPI_Data[Oils and fats],CPI_Data[Sector],L$32,CPI_Data[Date],$K42), SUMIFS(CPI_Data[Fruits],CPI_Data[Sector],L$32,CPI_Data[Date],$K42), SUMIFS(CPI_Data[Vegetables],CPI_Data[Sector],L$32,CPI_Data[Date],$K42), SUMIFS(CPI_Data[Pulses and products],CPI_Data[Sector],L$32,CPI_Data[Date],$K42), SUMIFS(CPI_Data[Sugar and Confectionery],CPI_Data[Sector],L$32,CPI_Data[Date],$K42), SUMIFS(CPI_Data[Spices],CPI_Data[Sector],L$32,CPI_Data[Date],$K42), SUMIFS(CPI_Data[Non-alcoholic beverages],CPI_Data[Sector],L$32,CPI_Data[Date],$K42), SUMIFS(CPI_Data[Prepared meals, snacks, sweets etc.],CPI_Data[Sector],L$32,CPI_Data[Date],$K42) ) -> 174.24167 | M42: =(L42-L41)/L41 -> -0.0082060526 | N42: =AVERAGE( SUMIFS(CPI_Data[Cereals and products],CPI_Data[Sector],N$32,CPI_Data[Date],$K42), SUMIFS(CPI_Data[Meat and fish],CPI_Data[Sector],N$32,CPI_Data[Date],$K42), SUMIFS(CPI_Data[Egg],CPI_Data[Sector],N$32,CPI_Data[Date],$K42), SUMIFS(CPI_Data[Milk and products],CPI_Data[Sector],N$32,CPI_Data[Date],$K42), SUMIFS(CPI_Data[Oils and fats],CPI_Data[Sector],N$32,CPI_Data[Date],$K42), SUMIFS(CPI_Data[Fruits],CPI_Data[Sector],N$32,CPI_Data[Date],$K42), SUMIFS(CPI_Data[Vegetables],CPI_Data[Sector],N$32,CPI_Data[Date],$K42), SUMIFS(CPI_Data[Pulses and products],CPI_Data[Sector],N$32,CPI_Data[Date],$K42), SUMIFS(CPI_Data[Sugar and Confectionery],CPI_Data[Sector],N$32,CPI_Data[Date],$K42), SUMIFS(CPI_Data[Spices],CPI_Data[Sector],N$32,CPI_Data[Date],$K42), SUMIFS(CPI_Data[Non-alcoholic beverages],CPI_Data[Sector],N$32,CPI_Data[Date],$K42), SUMIFS(CPI_Data[Prepared meals, snacks, sweets etc.],CPI_Data[Sector],N$32,CPI_Data[Date],$K42) ) -> 176.875 | O42: =(N42-N41)/N41 -> -0.0038485005 | P42: =AVERAGE( SUMIFS(CPI_Data[Cereals and products],CPI_Data[Sector],P$32,CPI_Data[Date],$K42), SUMIFS(CPI_Data[Meat and fish],CPI_Data[Sector],P$32,CPI_Data[Date],$K42), SUMIFS(CPI_Data[Egg],CPI_Data[Sector],P$32,CPI_Data[Date],$K42), SUMIFS(CPI_Data[Milk and products],CPI_Data[Sector],P$32,CPI_Data[Date],$K42), SUMIFS(CPI_Data[Oils and fats],CPI_Data[Sector],P$32,CPI_Data[Date],$K42), SUMIFS(CPI_Data[Fruits],CPI_Data[Sector],P$32,CPI_Data[Date],$K42), SUMIFS(CPI_Data[Vegetables],CPI_Data[Sector],P$32,CPI_Data[Date],$K42), SUMIFS(CPI_Data[Pulses and products],CPI_Data[Sector],P$32,CPI_Data[Date],$K42), SUMIFS(CPI_Data[Sugar and Confectionery],CPI_Data[Sector],P$32,CPI_Data[Date],$K42), SUMIFS(CPI_Data[Spices],CPI_Data[Sector],P$32,CPI_Data[Date],$K42), SUMIFS(CPI_Data[Non-alcoholic beverages],CPI_Data[Sector],P$32,CPI_Data[Date],$K42), SUMIFS(CPI_Data[Prepared meals, snacks, sweets etc.],CPI_Data[Sector],P$32,CPI_Data[Date],$K42) ) -> 175.175 | Q42: =(P42-P41)/P41 -> -0.0065689981
K43: 44986 | L43: =AVERAGE( SUMIFS(CPI_Data[Cereals and products],CPI_Data[Sector],L$32,CPI_Data[Date],$K43), SUMIFS(CPI_Data[Meat and fish],CPI_Data[Sector],L$32,CPI_Data[Date],$K43), SUMIFS(CPI_Data[Egg],CPI_Data[Sector],L$32,CPI_Data[Date],$K43), SUMIFS(CPI_Data[Milk and products],CPI_Data[Sector],L$32,CPI_Data[Date],$K43), SUMIFS(CPI_Data[Oils and fats],CPI_Data[Sector],L$32,CPI_Data[Date],$K43), SUMIFS(CPI_Data[Fruits],CPI_Data[Sector],L$32,CPI_Data[Date],$K43), SUMIFS(CPI_Data[Vegetables],CPI_Data[Sector],L$32,CPI_Data[Date],$K43), SUMIFS(CPI_Data[Pulses and products],CPI_Data[Sector],L$32,CPI_Data[Date],$K43), SUMIFS(CPI_Data[Sugar and Confectionery],CPI_Data[Sector],L$32,CPI_Data[Date],$K43), SUMIFS(CPI_Data[Spices],CPI_Data[Sector],L$32,CPI_Data[Date],$K43), SUMIFS(CPI_Data[Non-alcoholic beverages],CPI_Data[Sector],L$32,CPI_Data[Date],$K43), SUMIFS(CPI_Data[Prepared meals, snacks, sweets etc.],CPI_Data[Sector],L$32,CPI_Data[Date],$K43) ) -> 174.25 | M43: =(L43-L42)/L42 -> 4.7826295e-05 | N43: =AVERAGE( SUMIFS(CPI_Data[Cereals and products],CPI_Data[Sector],N$32,CPI_Data[Date],$K43), SUMIFS(CPI_Data[Meat and fish],CPI_Data[Sector],N$32,CPI_Data[Date],$K43), SUMIFS(CPI_Data[Egg],CPI_Data[Sector],N$32,CPI_Data[Date],$K43), SUMIFS(CPI_Data[Milk and products],CPI_Data[Sector],N$32,CPI_Data[Date],$K43), SUMIFS(CPI_Data[Oils and fats],CPI_Data[Sector],N$32,CPI_Data[Date],$K43), SUMIFS(CPI_Data[Fruits],CPI_Data[Sector],N$32,CPI_Data[Date],$K43), SUMIFS(CPI_Data[Vegetables],CPI_Data[Sector],N$32,CPI_Data[Date],$K43), SUMIFS(CPI_Data[Pulses and products],CPI_Data[Sector],N$32,CPI_Data[Date],$K43), SUMIFS(CPI_Data[Sugar and Confectionery],CPI_Data[Sector],N$32,CPI_Data[Date],$K43), SUMIFS(CPI_Data[Spices],CPI_Data[Sector],N$32,CPI_Data[Date],$K43), SUMIFS(CPI_Data[Non-alcoholic beverages],CPI_Data[Sector],N$32,CPI_Data[Date],$K43), SUMIFS(CPI_Data[Prepared meals, snacks, sweets etc.],CPI_Data[Sector],N$32,CPI_Data[Date],$K43) ) -> 176.88333 | O43: =(N43-N42)/N42 -> 4.7114252e-05 | P43: =AVERAGE( SUMIFS(CPI_Data[Cereals and products],CPI_Data[Sector],P$32,CPI_Data[Date],$K43), SUMIFS(CPI_Data[Meat and fish],CPI_Data[Sector],P$32,CPI_Data[Date],$K43), SUMIFS(CPI_Data[Egg],CPI_Data[Sector],P$32,CPI_Data[Date],$K43), SUMIFS(CPI_Data[Milk and products],CPI_Data[Sector],P$32,CPI_Data[Date],$K43), SUMIFS(CPI_Data[Oils and fats],CPI_Data[Sector],P$32,CPI_Data[Date],$K43), SUMIFS(CPI_Data[Fruits],CPI_Data[Sector],P$32,CPI_Data[Date],$K43), SUMIFS(CPI_Data[Vegetables],CPI_Data[Sector],P$32,CPI_Data[Date],$K43), SUMIFS(CPI_Data[Pulses and products],CPI_Data[Sector],P$32,CPI_Data[Date],$K43), SUMIFS(CPI_Data[Sugar and Confectionery],CPI_Data[Sector],P$32,CPI_Data[Date],$K43), SUMIFS(CPI_Data[Spices],CPI_Data[Sector],P$32,CPI_Data[Date],$K43), SUMIFS(CPI_Data[Non-alcoholic beverages],CPI_Data[Sector],P$32,CPI_Data[Date],$K43), SUMIFS(CPI_Data[Prepared meals, snacks, sweets etc.],CPI_Data[Sector],P$32,CPI_Data[Date],$K43) ) -> 175.18333 | Q43: =(P43-P42)/P42 -> 4.7571476e-05
K44: 45017 | L44: =AVERAGE( SUMIFS(CPI_Data[Cereals and products],CPI_Data[Sector],L$32,CPI_Data[Date],$K44), SUMIFS(CPI_Data[Meat and fish],CPI_Data[Sector],L$32,CPI_Data[Date],$K44), SUMIFS(CPI_Data[Egg],CPI_Data[Sector],L$32,CPI_Data[Date],$K44), SUMIFS(CPI_Data[Milk and products],CPI_Data[Sector],L$32,CPI_Data[Date],$K44), SUMIFS(CPI_Data[Oils and fats],CPI_Data[Sector],L$32,CPI_Data[Date],$K44), SUMIFS(CPI_Data[Fruits],CPI_Data[Sector],L$32,CPI_Data[Date],$K44), SUMIFS(CPI_Data[Vegetables],CPI_Data[Sector],L$32,CPI_Data[Date],$K44), SUMIFS(CPI_Data[Pulses and products],CPI_Data[Sector],L$32,CPI_Data[Date],$K44), SUMIFS(CPI_Data[Sugar and Confectionery],CPI_Data[Sector],L$32,CPI_Data[Date],$K44), SUMIFS(CPI_Data[Spices],CPI_Data[Sector],L$32,CPI_Data[Date],$K44), SUMIFS(CPI_Data[Non-alcoholic beverages],CPI_Data[Sector],L$32,CPI_Data[Date],$K44), SUMIFS(CPI_Data[Prepared meals, snacks, sweets etc.],CPI_Data[Sector],L$32,CPI_Data[Date],$K44) ) -> 174.89167 | M44: =(L44-L43)/L43 -> 0.0036824486 | N44: =AVERAGE( SUMIFS(CPI_Data[Cereals and products],CPI_Data[Sector],N$32,CPI_Data[Date],$K44), SUMIFS(CPI_Data[Meat and fish],CPI_Data[Sector],N$32,CPI_Data[Date],$K44), SUMIFS(CPI_Data[Egg],CPI_Data[Sector],N$32,CPI_Data[Date],$K44), SUMIFS(CPI_Data[Milk and products],CPI_Data[Sector],N$32,CPI_Data[Date],$K44), SUMIFS(CPI_Data[Oils and fats],CPI_Data[Sector],N$32,CPI_Data[Date],$K44), SUMIFS(CPI_Data[Fruits],CPI_Data[Sector],N$32,CPI_Data[Date],$K44), SUMIFS(CPI_Data[Vegetables],CPI_Data[Sector],N$32,CPI_Data[Date],$K44), SUMIFS(CPI_Data[Pulses and products],CPI_Data[Sector],N$32,CPI_Data[Date],$K44), SUMIFS(CPI_Data[Sugar and Confectionery],CPI_Data[Sector],N$32,CPI_Data[Date],$K44), SUMIFS(CPI_Data[Spices],CPI_Data[Sector],N$32,CPI_Data[Date],$K44), SUMIFS(CPI_Data[Non-alcoholic beverages],CPI_Data[Sector],N$32,CPI_Data[Date],$K44), SUMIFS(CPI_Data[Prepared meals, snacks, sweets etc.],CPI_Data[Sector],N$32,CPI_Data[Date],$K44) ) -> 177.96667 | O44: =(N44-N43)/N43 -> 0.0061245642 | P44: =AVERAGE( SUMIFS(CPI_Data[Cereals and products],CPI_Data[Sector],P$32,CPI_Data[Date],$K44), SUMIFS(CPI_Data[Meat and fish],CPI_Data[Sector],P$32,CPI_Data[Date],$K44), SUMIFS(CPI_Data[Egg],CPI_Data[Sector],P$32,CPI_Data[Date],$K44), SUMIFS(CPI_Data[Milk and products],CPI_Data[Sector],P$32,CPI_Data[Date],$K44), SUMIFS(CPI_Data[Oils and fats],CPI_Data[Sector],P$32,CPI_Data[Date],$K44), SUMIFS(CPI_Data[Fruits],CPI_Data[Sector],P$32,CPI_Data[Date],$K44), SUMIFS(CPI_Data[Vegetables],CPI_Data[Sector],P$32,CPI_Data[Date],$K44), SUMIFS(CPI_Data[Pulses and products],CPI_Data[Sector],P$32,CPI_Data[Date],$K44), SUMIFS(CPI_Data[Sugar and Confectionery],CPI_Data[Sector],P$32,CPI_Data[Date],$K44), SUMIFS(CPI_Data[Spices],CPI_Data[Sector],P$32,CPI_Data[Date],$K44), SUMIFS(CPI_Data[Non-alcoholic beverages],CPI_Data[Sector],P$32,CPI_Data[Date],$K44), SUMIFS(CPI_Data[Prepared meals, snacks, sweets etc.],CPI_Data[Sector],P$32,CPI_Data[Date],$K44) ) -> 175.975 | Q44: =(P44-P43)/P43 -> 0.0045190753
K45: 45047 | L45: =AVERAGE( SUMIFS(CPI_Data[Cereals and products],CPI_Data[Sector],L$32,CPI_Data[Date],$K45), SUMIFS(CPI_Data[Meat and fish],CPI_Data[Sector],L$32,CPI_Data[Date],$K45), SUMIFS(CPI_Data[Egg],CPI_Data[Sector],L$32,CPI_Data[Date],$K45), SUMIFS(CPI_Data[Milk and products],CPI_Data[Sector],L$32,CPI_Data[Date],$K45), SUMIFS(CPI_Data[Oils and fats],CPI_Data[Sector],L$32,CPI_Data[Date],$K45), SUMIFS(CPI_Data[Fruits],CPI_Data[Sector],L$32,CPI_Data[Date],$K45), SUMIFS(CPI_Data[Vegetables],CPI_Data[Sector],L$32,CPI_Data[Date],$K45), SUMIFS(CPI_Data[Pulses and products],CPI_Data[Sector],L$32,CPI_Data[Date],$K45), SUMIFS(CPI_Data[Sugar and Confectionery],CPI_Data[Sector],L$32,CPI_Data[Date],$K45), SUMIFS(CPI_Data[Spices],CPI_Data[Sector],L$32,CPI_Data[Date],$K45), SUMIFS(CPI_Data[Non-alcoholic beverages],CPI_Data[Sector],L$32,CPI_Data[Date],$K45), SUMIFS(CPI_Data[Prepared meals, snacks, sweets etc.],CPI_Data[Sector],L$32,CPI_Data[Date],$K45) ) -> 176.15833 | M45: =(L45-L44)/L44 -> 0.0072425787 | N45: =AVERAGE( SUMIFS(CPI_Data[Cereals and products],CPI_Data[Sector],N$32,CPI_Data[Date],$K45), SUMIFS(CPI_Data[Meat and fish],CPI_Data[Sector],N$32,CPI_Data[Date],$K45), SUMIFS(CPI_Data[Egg],CPI_Data[Sector],N$32,CPI_Data[Date],$K45), SUMIFS(CPI_Data[Milk and products],CPI_Data[Sector],N$32,CPI_Data[Date],$K45), SUMIFS(CPI_Data[Oils and fats],CPI_Data[Sector],N$32,CPI_Data[Date],$K45), SUMIFS(CPI_Data[Fruits],CPI_Data[Sector],N$32,CPI_Data[Date],$K45), SUMIFS(CPI_Data[Vegetables],CPI_Data[Sector],N$32,CPI_Data[Date],$K45), SUMIFS(CPI_Data[Pulses and products],CPI_Data[Sector],N$32,CPI_Data[Date],$K45), SUMIFS(CPI_Data[Sugar and Confectionery],CPI_Data[Sector],N$32,CPI_Data[Date],$K45), SUMIFS(CPI_Data[Spices],CPI_Data[Sector],N$32,CPI_Data[Date],$K45), SUMIFS(CPI_Data[Non-alcoholic beverages],CPI_Data[Sector],N$32,CPI_Data[Date],$K45), SUMIFS(CPI_Data[Prepared meals, snacks, sweets etc.],CPI_Data[Sector],N$32,CPI_Data[Date],$K45) ) -> 179.33333 | O45: =(N45-N44)/N44 -> 0.0076793407 | P45: =AVERAGE( SUMIFS(CPI_Data[Cereals and products],CPI_Data[Sector],P$32,CPI_Data[Date],$K45), SUMIFS(CPI_Data[Meat and fish],CPI_Data[Sector],P$32,CPI_Data[Date],$K45), SUMIFS(CPI_Data[Egg],CPI_Data[Sector],P$32,CPI_Data[Date],$K45), SUMIFS(CPI_Data[Milk and products],CPI_Data[Sector],P$32,CPI_Data[Date],$K45), SUMIFS(CPI_Data[Oils and fats],CPI_Data[Sector],P$32,CPI_Data[Date],$K45), SUMIFS(CPI_Data[Fruits],CPI_Data[Sector],P$32,CPI_Data[Date],$K45), SUMIFS(CPI_Data[Vegetables],CPI_Data[Sector],P$32,CPI_Data[Date],$K45), SUMIFS(CPI_Data[Pulses and products],CPI_Data[Sector],P$32,CPI_Data[Date],$K45), SUMIFS(CPI_Data[Sugar and Confectionery],CPI_Data[Sector],P$32,CPI_Data[Date],$K45), SUMIFS(CPI_Data[Spices],CPI_Data[Sector],P$32,CPI_Data[Date],$K45), SUMIFS(CPI_Data[Non-alcoholic beverages],CPI_Data[Sector],P$32,CPI_Data[Date],$K45), SUMIFS(CPI_Data[Prepared meals, snacks, sweets etc.],CPI_Data[Sector],P$32,CPI_Data[Date],$K45) ) -> 177.31667 | Q45: =(P45-P44)/P44 -> 0.007624189
B81: Rural | G81: Urban | K81: Rural+Urban
B82: Food Categories | C82: 44713 | D82: 45047 | E82: Absolute Change Rural | F82: Change Percentage | G82: 44713 | H82: 45047 | I82: Absolute Change Urban | J82: Change Percentage | K82: 44713 | L82: 45047 | M82: Absolute Change Rural+Urban | N82: Change Percentage
B83: Spices | C83: {=INDEX(CPI_Data[#Data],MATCH(1,(CPI_Data[Sector]=$B$81)*(CPI_Data[Date]=C$82),0),MATCH($B83,CPI_Data[#Headers],0))} -> 188.9 | D83: {=INDEX(CPI_Data[#Data], MATCH(1,(CPI_Data[Sector]=$B$81)*(CPI_Data[Date] = $D$82),0), MATCH($B83,CPI_Data[#Headers],0))} -> 221 | E83: =D83-C83 -> 32.1 | F83: =(D83-C83)/C83 -> 0.16993118 | G83: {=INDEX(CPI_Data[#Data], MATCH(1,(CPI_Data[Sector] = $G$81)*(CPI_Data[Date] = G$82),0), MATCH($B83,CPI_Data[#Headers],0))} -> 183.5 | H83: {=INDEX(CPI_Data[#Data], MATCH(1,(CPI_Data[Sector] = $G$81)*(CPI_Data[Date] = H$82),0), MATCH($B83,CPI_Data[#Headers],0))} -> 211.9 | I83: =H83-G83 -> 28.4 | J83: =(H83-G83)/G83 -> 0.15476839 | K83: {=INDEX(CPI_Data[#Data], MATCH(1,(CPI_Data[Sector] = $K$81)*(CPI_Data[Date] = K$82),0), MATCH($B83,CPI_Data[#Headers],0))} -> 187.1 | L83: {=INDEX(CPI_Data[#Data], MATCH(1,(CPI_Data[Sector] = $K$81)*(CPI_Data[Date] = L$82),0), MATCH($B83,CPI_Data[#Headers],0))} -> 218 | M83: =L83-K83 -> 30.9 | N83: =(L83-K83)/K83 -> 0.16515232
B84: Cereals and products | C84: {=INDEX(CPI_Data[#Data],MATCH(1,(CPI_Data[Sector]=$B$81)*(CPI_Data[Date]=C$82),0),MATCH($B84,CPI_Data[#Headers],0))} -> 153.8 | D84: {=INDEX(CPI_Data[#Data], MATCH(1,(CPI_Data[Sector]=$B$81)*(CPI_Data[Date] = $D$82),0), MATCH($B84,CPI_Data[#Headers],0))} -> 173.2 | E84: =D84-C84 -> 19.4 | F84: =(D84-C84)/C84 -> 0.12613784 | G84: {=INDEX(CPI_Data[#Data], MATCH(1,(CPI_Data[Sector] = $G$81)*(CPI_Data[Date] = G$82),0), MATCH($B84,CPI_Data[#Headers],0))} -> 157.5 | H84: {=INDEX(CPI_Data[#Data], MATCH(1,(CPI_Data[Sector] = $G$81)*(CPI_Data[Date] = H$82),0), MATCH($B84,CPI_Data[#Headers],0))} -> 174.7 | I84: =H84-G84 -> 17.2 | J84: =(H84-G84)/G84 -> 0.10920635 | K84: {=INDEX(CPI_Data[#Data], MATCH(1,(CPI_Data[Sector] = $K$81)*(CPI_Data[Date] = K$82),0), MATCH($B84,CPI_Data[#Headers],0))} -> 155 | L84: {=INDEX(CPI_Data[#Data], MATCH(1,(CPI_Data[Sector] = $K$81)*(CPI_Data[Date] = L$82),0), MATCH($B84,CPI_Data[#Headers],0))} -> 173.7 | M84: =L84-K84 -> 18.7 | N84: =(L84-K84)/K84 -> 0.12064516
B85: Milk and products | C85: {=INDEX(CPI_Data[#Data],MATCH(1,(CPI_Data[Sector]=$B$81)*(CPI_Data[Date]=C$82),0),MATCH($B85,CPI_Data[#Headers],0))} -> 165.4 | D85: {=INDEX(CPI_Data[#Data], MATCH(1,(CPI_Data[Sector]=$B$81)*(CPI_Data[Date] = $D$82),0), MATCH($B85,CPI_Data[#Headers],0))} -> 179.6 | E85: =D85-C85 -> 14.2 | F85: =(D85-C85)/C85 -> 0.085852479 | G85: {=INDEX(CPI_Data[#Data], MATCH(1,(CPI_Data[Sector] = $G$81)*(CPI_Data[Date] = G$82),0), MATCH($B85,CPI_Data[#Headers],0))} -> 166.4 | H85: {=INDEX(CPI_Data[#Data], MATCH(1,(CPI_Data[Sector] = $G$81)*(CPI_Data[Date] = H$82),0), MATCH($B85,CPI_Data[#Headers],0))} -> 179.4 | I85: =H85-G85 -> 13 | J85: =(H85-G85)/G85 -> 0.078125 | K85: {=INDEX(CPI_Data[#Data], MATCH(1,(CPI_Data[Sector] = $K$81)*(CPI_Data[Date] = K$82),0), MATCH($B85,CPI_Data[#Headers],0))} -> 165.8 | L85: {=INDEX(CPI_Data[#Data], MATCH(1,(CPI_Data[Sector] = $K$81)*(CPI_Data[Date] = L$82),0), MATCH($B85,CPI_Data[#Headers],0))} -> 179.5 | M85: =L85-K85 -> 13.7 | N85: =(L85-K85)/K85 -> 0.082629674
B86: Pulses and products | C86: {=INDEX(CPI_Data[#Data],MATCH(1,(CPI_Data[Sector]=$B$81)*(CPI_Data[Date]=C$82),0),MATCH($B86,CPI_Data[#Headers],0))} -> 164.6 | D86: {=INDEX(CPI_Data[#Data], MATCH(1,(CPI_Data[Sector]=$B$81)*(CPI_Data[Date] = $D$82),0), MATCH($B86,CPI_Data[#Headers],0))} -> 174.9 | E86: =D86-C86 -> 10.3 | F86: =(D86-C86)/C86 -> 0.062575942 | G86: {=INDEX(CPI_Data[#Data], MATCH(1,(CPI_Data[Sector] = $G$81)*(CPI_Data[Date] = G$82),0), MATCH($B86,CPI_Data[#Headers],0))} -> 163.6 | H86: {=INDEX(CPI_Data[#Data], MATCH(1,(CPI_Data[Sector] = $G$81)*(CPI_Data[Date] = H$82),0), MATCH($B86,CPI_Data[#Headers],0))} -> 176.9 | I86: =H86-G86 -> 13.3 | J86: =(H86-G86)/G86 -> 0.081295844 | K86: {=INDEX(CPI_Data[#Data], MATCH(1,(CPI_Data[Sector] = $K$81)*(CPI_Data[Date] = K$82),0), MATCH($B86,CPI_Data[#Headers],0))} -> 164.3 | L86: {=INDEX(CPI_Data[#Data], MATCH(1,(CPI_Data[Sector] = $K$81)*(CPI_Data[Date] = L$82),0), MATCH($B86,CPI_Data[#Headers],0))} -> 175.6 | M86: =L86-K86 -> 11.3 | N86: =(L86-K86)/K86 -> 0.068776628
B87: Prepared meals, snacks, sweets etc. | C87: {=INDEX(CPI_Data[#Data],MATCH(1,(CPI_Data[Sector]=$B$81)*(CPI_Data[Date]=C$82),0),MATCH($B87,CPI_Data[#Headers],0))} -> 181.9 | D87: {=INDEX(CPI_Data[#Data], MATCH(1,(CPI_Data[Sector]=$B$81)*(CPI_Data[Date] = $D$82),0), MATCH($B87,CPI_Data[#Headers],0))} -> 191.1 | E87: =D87-C87 -> 9.2 | F87: =(D87-C87)/C87 -> 0.05057724 | G87: {=INDEX(CPI_Data[#Data], MATCH(1,(CPI_Data[Sector] = $G$81)*(CPI_Data[Date] = G$82),0), MATCH($B87,CPI_Data[#Headers],0))} -> 186.3 | H87: {=INDEX(CPI_Data[#Data], MATCH(1,(CPI_Data[Sector] = $G$81)*(CPI_Data[Date] = H$82),0), MATCH($B87,CPI_Data[#Headers],0))} -> 197.7 | I87: =H87-G87 -> 11.4 | J87: =(H87-G87)/G87 -> 0.061191626 | K87: {=INDEX(CPI_Data[#Data], MATCH(1,(CPI_Data[Sector] = $K$81)*(CPI_Data[Date] = K$82),0), MATCH($B87,CPI_Data[#Headers],0))} -> 183.9 | L87: {=INDEX(CPI_Data[#Data], MATCH(1,(CPI_Data[Sector] = $K$81)*(CPI_Data[Date] = L$82),0), MATCH($B87,CPI_Data[#Headers],0))} -> 194.2 | M87: =L87-K87 -> 10.3 | N87: =(L87-K87)/K87 -> 0.0560087
